<?xml version="1.0" ?>
<!-- =================================================================================== -->
<!-- |    This document was autogenerated by xacro from lbr_iiwa_14_r820.xacro         | -->
<!-- |    EDITING THIS FILE BY HAND IS NOT RECOMMENDED                                 | -->
<!-- =================================================================================== -->
<robot name="kuka_lbr_iiwa_14_r820" xmlns:xacro="http://wiki.ros.org/xacro">
  <!-- link list -->
  <link name="base_link">
    <visual>
      <origin rpy="0 0 0" xyz="0 0 0"/>
      <geometry>
        <mesh filename="package://kuka_lbr_iiwa_support/meshes/lbr_iiwa_14_r820/visual/base_link.dae"/>
      </geometry>
      <material name="black">
        <color rgba="0 0 0 1"/>
      </material>
    </visual>
    <collision>
      <origin rpy="0 0 0" xyz="0 0 0"/>
      <geometry>
        <mesh filename="package://kuka_lbr_iiwa_support/meshes/lbr_iiwa_14_r820/collision/base_link.stl"/>
      </geometry>
    </collision>
  </link>
  <link name="link_1">
    <visual>
      <origin rpy="0 0 0" xyz="0 0 0"/>
      <geometry>
        <mesh filename="package://kuka_lbr_iiwa_support/meshes/lbr_iiwa_14_r820/visual/link_1.dae"/>
      </geometry>
      <material name="Green">
        <color rgba="0 1 0 1"/>
      </material>
    </visual>
    <collision>
      <origin rpy="0 0 0" xyz="0 0 0"/>
      <geometry>
        <mesh filename="package://kuka_lbr_iiwa_support/meshes/lbr_iiwa_14_r820/collision/link_1.stl"/>
      </geometry>
    </collision>
  </link>
  <link name="link_2">
    <visual>
      <origin rpy="0 0 0" xyz="0 0 0"/>
      <geometry>
        <mesh filename="package://kuka_lbr_iiwa_support/meshes/lbr_iiwa_14_r820/visual/link_2.dae"/>
      </geometry>
      <material name="Blue">
        <color rgba="0 0 1 1"/>
      </material>
    </visual>
    <collision>
      <origin rpy="0 0 0" xyz="0 0 0"/>
      <geometry>
        <mesh filename="package://kuka_lbr_iiwa_support/meshes/lbr_iiwa_14_r820/collision/link_2.stl"/>
      </geometry>
    </collision>
  </link>
  <link name="link_3">
    <visual>
      <origin rpy="0 0 0" xyz="0 0 0"/>
      <geometry>
        <mesh filename="package://kuka_lbr_iiwa_support/meshes/lbr_iiwa_14_r820/visual/link_3.dae"/>
      </geometry>
      <material name="Green">
        <color rgba="0 1 0 1"/>
      </material>
    </visual>
    <collision>
      <origin rpy="0 0 0" xyz="0 0 0"/>
      <geometry>
        <mesh filename="package://kuka_lbr_iiwa_support/meshes/lbr_iiwa_14_r820/collision/link_3.stl"/>
      </geometry>
    </collision>
  </link>
  <link name="link_4">
    <visual>
      <origin rpy="0 0 0" xyz="0 0 0"/>
      <geometry>
        <mesh filename="package://kuka_lbr_iiwa_support/meshes/lbr_iiwa_14_r820/visual/link_4.dae"/>
      </geometry>
      <material name="Blue">
        <color rgba="0 0 1 1"/>
      </material>
    </visual>
    <collision>
      <origin rpy="0 0 0" xyz="0 0 0"/>
      <geometry>
        <mesh filename="package://kuka_lbr_iiwa_support/meshes/lbr_iiwa_14_r820/collision/link_4.stl"/>
      </geometry>
    </collision>
  </link>
  <link name="link_5">
    <visual>
      <origin rpy="0 0 0" xyz="0 0 0"/>
      <geometry>
        <mesh filename="package://kuka_lbr_iiwa_support/meshes/lbr_iiwa_14_r820/visual/link_5.dae"/>
      </geometry>
      <material name="Green">
        <color rgba="0 1 0 1"/>
      </material>
    </visual>
    <collision>
      <origin rpy="0 0 0" xyz="0 0 0"/>
      <geometry>
        <mesh filename="package://kuka_lbr_iiwa_support/meshes/lbr_iiwa_14_r820/collision/link_5.stl"/>
      </geometry>
    </collision>
  </link>
  <link name="link_6">
    <visual>
      <origin rpy="0 0 0" xyz="0 0 0"/>
      <geometry>
        <mesh filename="package://kuka_lbr_iiwa_support/meshes/lbr_iiwa_14_r820/visual/link_6.dae"/>
      </geometry>
      <material name="Blue">
        <color rgba="0 0 1 1"/>
      </material>
    </visual>
    <collision>
      <origin rpy="0 0 0" xyz="0 0 0"/>
      <geometry>
        <mesh filename="package://kuka_lbr_iiwa_support/meshes/lbr_iiwa_14_r820/collision/link_6.stl"/>
      </geometry>
    </collision>
  </link>
  <link name="link_7">
    <visual>
      <origin rpy="0 0 0" xyz="0 0 0"/>
      <geometry>
        <mesh filename="package://kuka_lbr_iiwa_support/meshes/lbr_iiwa_14_r820/visual/link_7.dae"/>
      </geometry>
      <material name="">
        <color rgba="0 1 0 1"/>
      </material>
    </visual>
    <collision>
      <origin rpy="0 0 0" xyz="0 0 0"/>
      <geometry>
        <mesh filename="package://kuka_lbr_iiwa_support/meshes/lbr_iiwa_14_r820/collision/link_7.stl"/>
      </geometry>
    </collision>
  </link>
  <link name="tool0"/>

  <!-- End Effector (Suction Gripper) -->
  <link name="suction_gripper">
    <!-- Collision shape -->
    
    <collision>
        <origin rpy="0 0 0" xyz="0 0 0"/>
        <geometry>
            <cylinder radius="0.04" length="0.05"/>  <!-- 5 cm radius, 10 cm length -->
        </geometry>
    </collision>

    <!-- Visual shape -->
    <visual>
        <origin rpy="0 0 0" xyz="0 0 0"/>
        <geometry>
            <cylinder radius="0.04" length="0.05"/>
        </geometry>
        <material name="red">
            <color rgba="1 0 0 1"/>
        </material>
    </visual>

    <!-- Inertial properties -->
    <inertial>
        <mass value="0.2"/>  <!-- 200g mass -->
        <inertia ixx="0.0001" ixy="0" ixz="0" iyy="0.0001" iyz="0" izz="0.0001"/>
        <origin xyz="0 0 0"/>
    </inertial>
  </link>


  <!-- end of link list -->
  <!-- joint list -->
  <joint name="joint_a1" type="revolute">
    <origin rpy="0 0 0" xyz="0 0 0"/>
    <parent link="base_link"/>
    <child link="link_1"/>
    <axis xyz="0 0 1"/>
    <limit effort="0" lower="-2.9668" upper="2.9668" velocity="1.4834"/>
  </joint>
  <joint name="joint_a2" type="revolute">
    <origin rpy="0 0 0" xyz="-0.00043624 0 0.36"/>
    <parent link="link_1"/>
    <child link="link_2"/>
    <axis xyz="0 1 0"/>
    <limit effort="0" lower="-2.0942" upper="2.0942" velocity="1.4834"/>
  </joint>
  <joint name="joint_a3" type="revolute">
    <origin rpy="0 0 0" xyz="0 0 0"/>
    <parent link="link_2"/>
    <child link="link_3"/>
    <axis xyz="0 0 1"/>
    <limit effort="0" lower="-2.9668" upper="2.9668" velocity="1.7452"/>
  </joint>
  <joint name="joint_a4" type="revolute">
    <origin rpy="0 0 0" xyz="0.00043624 0 0.42"/>
    <parent link="link_3"/>
    <child link="link_4"/>
    <axis xyz="0 -1 0"/>
    <limit effort="0" lower="-2.0942" upper="2.0942" velocity="1.3089"/>
  </joint>
  <joint name="joint_a5" type="revolute">
    <origin rpy="0 0 0" xyz="0 0 0"/>
    <parent link="link_4"/>
    <child link="link_5"/>
    <axis xyz="0 0 1"/>
    <limit effort="0" lower="-2.9668" upper="2.9668" velocity="2.2688"/>
  </joint>
  <joint name="joint_a6" type="revolute">
    <origin rpy="0 0 0" xyz="0 0 0.4"/>
    <parent link="link_5"/>
    <child link="link_6"/>
    <axis xyz="0 1 0"/>
    <limit effort="0" lower="-2.0942" upper="2.0942" velocity="2.356"/>
  </joint>
  <joint name="joint_a7" type="revolute">
    <origin rpy="0 0 0" xyz="0 0 0"/>
    <parent link="link_6"/>
    <child link="link_7"/>
    <axis xyz="0 0 1"/>
    <limit effort="0" lower="-3.0541" upper="3.0541" velocity="2.356"/>
  </joint>
  <joint name="joint_a7-tool0" type="fixed">
    <origin rpy="0 0 0" xyz="0 0 0.126"/>
    <parent link="link_7"/>
    <child link="tool0"/>
    <axis xyz="0 0 0"/>
  </joint>
  <!-- Joint to attach gripper to last robot link -->
  <joint name="suction_joint" type="fixed">
    <origin rpy="0 0 0" xyz="0 0 0.02"/>
    <parent link="tool0"/>  <!-- Attach to last link (UR10 end-effector) -->
    <child link="suction_gripper"/>
    <origin xyz="0 0 0.1"/>  <!-- Adjust position (10cm forward) -->
  </joint>

  <!-- end of joint list -->
  <!-- ROS base_link to KUKA $ROBROOT coordinate system transform -->
  <link name="base"/>
  <joint name="base_link-base" type="fixed">
    <origin rpy="0 0 0" xyz="0 0 0"/>
    <parent link="base_link"/>
    <child link="base"/>
  </joint>
</robot>

